Workbook

Sheet Rekap Neraca Pengelolaan Sampah
A1: Rekap Neraca Sampah
A2: Periode | C2: JULI | D2: 2024 | E2: - | F2: JUNI | G2: 2025
A3: Perusahaan | C3: PT PELINDO DAYA SEJAHTERA
A5: No | B5: Sumber Sampah | D5: Jumlah Timbulan Sampah (ton/tahun) | E5: Penanganan Sampah (ton/tahun)
E6: Jumlah Sampah Organik | F6: Jumlah Sampah Anorganik Terpilah | G6: Total Sampah Terkelola | H6: Prosentase Sampah Terkelola | I6: Jumlah Sampah Lainnya dan/atau residu | J6: Total Sampah Lainnya dan/atau residu | K6: Prosentase Sampah Lainnya dan/atau residu
A7: 1 | B7: Area Kantor | D7: =E7+F7+I7 -> 68.97579 | E7: ='Rekap area'!D20 -> 37.1225 | F7: ='Rekap area'!E20 -> 4.01729 | G7: =E7+F7 -> 41.13979 | H7: =G7/D7 -> 0.59643811 | I7: ='Rekap area'!F20 -> 27.836 | J7: =I7 -> 27.836 | K7: =J7/D7 -> 0.40356189
A8: 2 | B8: Area Tempat Parkir/Taman/Jalan | D8: =E8+F8+I8 -> 168.83385 | E8: ='Rekap area'!H20 -> 99.9736 | F8: ='Rekap area'!I20 -> 5.002024 | G8: =E8+F8 -> 104.97562 | H8: =G8/D8 -> 0.62176881 | I8: ='Rekap area'!J20 -> 63.858228 | J8: =I8 -> 63.858228 | K8: =J8/D8 -> 0.37823119
A9: 3 | B9: Area Ruang Tunggu | D9: =E9+F9+I9 -> 47.80944 | E9: ='Rekap area'!L20 -> 27.2483 | F9: ='Rekap area'!M20 -> 3.07164 | G9: =E9+F9 -> 30.31994 | H9: =G9/D9 -> 0.63418312 | I9: ='Rekap area'!N20 -> 17.4895 | J9: =I9 -> 17.4895 | K9: =J9/D9 -> 0.36581688
A10: 4 | B10: Area Tempat Makan | D10: =E10+F10+I10 -> 259.28452 | E10: ='Rekap area'!P20 -> 140.07774 | F10: ='Rekap area'!Q20 -> 11.26788 | G10: =E10+F10 -> 151.34562 | H10: =G10/D10 -> 0.5837048 | I10: ='Rekap area'!R20 -> 107.9389 | J10: =I10 -> 107.9389 | K10: =J10/D10 -> 0.4162952
A11: 5 | B11: Sampah Kapal (Khusus Pelabuhan) | D11: =E11+F11+I11 -> 84.2502 | E11: ='Rekap area'!T20 -> 48.661 | F11: ='Rekap area'!U20 -> 3.4922 | G11: =E11+F11 -> 52.1532 | H11: =G11/D11 -> 0.61902761 | I11: ='Rekap area'!V20 -> 32.097 | J11: =I11 -> 32.097 | K11: =J11/D11 -> 0.38097239
A12: 6 | B12: Area Lain (sebutkan jika ada) | D12: =E12+F12+I12 -> 50.25496 | E12: ='Rekap area'!X20 -> 22.673 | F12: ='Rekap area'!Y20 -> 9.06996 | G12: =E12+F12 -> 31.74296 | H12: =G12/D12 -> 0.63163835 | I12: ='Rekap area'!Z20 -> 18.512 | J12: =I12 -> 18.512 | K12: =J12/D12 -> 0.36836165
B13: Total (ton/tahun) | D13: =SUM(D7:D12) -> 679.40876 | E13: =SUM(E7:E12) -> 375.75614 | F13: =SUM(F7:F12) -> 35.920994 | G13: =SUM(G7:G12) -> 411.67713 | H13: =G13/D13 -> 0.60593439 | I13: =SUM(I7:I12) -> 267.73163 | J13: =SUM(J7:J12) -> 267.73163 | K13: =J13/D13 -> 0.39406561
C15: Mengetahui, | I15: (kab/kota), tgl-bulan-tahun
C16: Jabatan Pimpinan | I16: Jabatan Penyusun
C18: ttd+cap | I18: ttd
C20: nama pimpinan | I20: nama penyusun
C21: nopeg/nip | I21: nopeg/nip
A23: … | B23: : Tahun dan nama perusahaan mohon diisi

Sheet Rekap Sampah terkelola
A1: Rekap Jumlah Sampah Terkelola
A2: Berdasarkan Jenis Sampah Terpilah
A3: Periode | C3: JULI | D3: ='Rekap Neraca Pengelolaan Sampah'!D2 -> 2024 | E3: - | F3: JUNI | G3: ='Rekap Neraca Pengelolaan Sampah'!G2 -> 2025
A4: Perusahaan | C4: ='Rekap Neraca Pengelolaan Sampah'!C3 -> PT PELINDO DAYA SEJAHTERA
A6: No | B6: Bulan | C6: Tahun | D6: Sampah Terkelola | G6: Jumlah Timbulan Sampah (ton/bulan)
D7: Jumlah Sampah Organik Terpilah (ton/bulan) | E7: Jumlah Sampah Anorganik Terpilah (ton/bulan) | F7: Jumlah Sampah Lainnya dan/atau Residu (ton/bulan)
A8: 1 | B8: Juli | C8: =$D$3 -> 2024 | D8: ='Rekap area'!D8+'Rekap area'!H8+'Rekap area'!L8+'Rekap area'!P8+'Rekap area'!T8+'Rekap area'!X8 -> 59.4644 | E8: ='Rekap area'!E8+'Rekap area'!I8+'Rekap area'!M8+'Rekap area'!Q8+'Rekap area'!U8+'Rekap area'!Y8 -> 10.354968 | F8: ='Rekap area'!F8+'Rekap area'!J8+'Rekap area'!N8+'Rekap area'!R8+'Rekap area'!V8+'Rekap area'!Z8 -> 26.97 | G8: =SUM(D8:F8) -> 96.789368
A9: 2 | B9: Agustus | C9: =$D$3 -> 2024 | D9: ='Rekap area'!D9+'Rekap area'!H9+'Rekap area'!L9+'Rekap area'!P9+'Rekap area'!T9+'Rekap area'!X9 -> 44.9416 | E9: ='Rekap area'!E9+'Rekap area'!I9+'Rekap area'!M9+'Rekap area'!Q9+'Rekap area'!U9+'Rekap area'!Y9 -> 8.738652 | F9: ='Rekap area'!F9+'Rekap area'!J9+'Rekap area'!N9+'Rekap area'!R9+'Rekap area'!V9+'Rekap area'!Z9 -> 28.465 | G9: =SUM(D9:F9) -> 82.145252
A10: 3 | B10: September | C10: =$D$3 -> 2024 | D10: ='Rekap area'!D10+'Rekap area'!H10+'Rekap area'!L10+'Rekap area'!P10+'Rekap area'!T10+'Rekap area'!X10 -> 1.5576 | E10: ='Rekap area'!E10+'Rekap area'!I10+'Rekap area'!M10+'Rekap area'!Q10+'Rekap area'!U10+'Rekap area'!Y10 -> 1.85874 | F10: ='Rekap area'!F10+'Rekap area'!J10+'Rekap area'!N10+'Rekap area'!R10+'Rekap area'!V10+'Rekap area'!Z10 -> 46.117 | G10: =SUM(D10:F10) -> 49.53334
A11: 4 | B11: Oktober | C11: =$D$3 -> 2024 | D11: ='Rekap area'!D11+'Rekap area'!H11+'Rekap area'!L11+'Rekap area'!P11+'Rekap area'!T11+'Rekap area'!X11 -> 1.2324 | E11: ='Rekap area'!E11+'Rekap area'!I11+'Rekap area'!M11+'Rekap area'!Q11+'Rekap area'!U11+'Rekap area'!Y11 -> 2.54644 | F11: ='Rekap area'!F11+'Rekap area'!J11+'Rekap area'!N11+'Rekap area'!R11+'Rekap area'!V11+'Rekap area'!Z11 -> 45.683 | G11: =SUM(D11:F11) -> 49.46184
A12: 5 | B12: November | C12: =$D$3 -> 2024 | D12: ='Rekap area'!D12+'Rekap area'!H12+'Rekap area'!L12+'Rekap area'!P12+'Rekap area'!T12+'Rekap area'!X12 -> 49.8958 | E12: ='Rekap area'!E12+'Rekap area'!I12+'Rekap area'!M12+'Rekap area'!Q12+'Rekap area'!U12+'Rekap area'!Y12 -> 2.669524 | F12: ='Rekap area'!F12+'Rekap area'!J12+'Rekap area'!N12+'Rekap area'!R12+'Rekap area'!V12+'Rekap area'!Z12 -> 29.893 | G12: =SUM(D12:F12) -> 82.458324
A13: 6 | B13: Desember | C13: =$D$3 -> 2024 | D13: ='Rekap area'!D13+'Rekap area'!H13+'Rekap area'!L13+'Rekap area'!P13+'Rekap area'!T13+'Rekap area'!X13 -> 95.80844 | E13: ='Rekap area'!E13+'Rekap area'!I13+'Rekap area'!M13+'Rekap area'!Q13+'Rekap area'!U13+'Rekap area'!Y13 -> 1.92192 | F13: ='Rekap area'!F13+'Rekap area'!J13+'Rekap area'!N13+'Rekap area'!R13+'Rekap area'!V13+'Rekap area'!Z13 -> 45.562 | G13: =SUM(D13:F13) -> 143.29236
A14: 7 | B14: Januari | C14: =$G$3 -> 2025 | D14: ='Rekap area'!D14+'Rekap area'!H14+'Rekap area'!L14+'Rekap area'!P14+'Rekap area'!T14+'Rekap area'!X14 -> 16.8012 | E14: ='Rekap area'!E14+'Rekap area'!I14+'Rekap area'!M14+'Rekap area'!Q14+'Rekap area'!U14+'Rekap area'!Y14 -> 2.03684 | F14: ='Rekap area'!F14+'Rekap area'!J14+'Rekap area'!N14+'Rekap area'!R14+'Rekap area'!V14+'Rekap area'!Z14 -> 25.780628 | G14: =SUM(D14:F14) -> 44.618668
A15: 8 | B15: Februari | C15: =$G$3 -> 2025 | D15: ='Rekap area'!D15+'Rekap area'!H15+'Rekap area'!L15+'Rekap area'!P15+'Rekap area'!T15+'Rekap area'!X15 -> 68.7818 | E15: ='Rekap area'!E15+'Rekap area'!I15+'Rekap area'!M15+'Rekap area'!Q15+'Rekap area'!U15+'Rekap area'!Y15 -> 1.89592 | F15: ='Rekap area'!F15+'Rekap area'!J15+'Rekap area'!N15+'Rekap area'!R15+'Rekap area'!V15+'Rekap area'!Z15 -> 12.5 | G15: =SUM(D15:F15) -> 83.17772
A16: 9 | B16: Maret | C16: =$G$3 -> 2025 | D16: ='Rekap area'!D16+'Rekap area'!H16+'Rekap area'!L16+'Rekap area'!P16+'Rekap area'!T16+'Rekap area'!X16 -> 14.9259 | E16: ='Rekap area'!E16+'Rekap area'!I16+'Rekap area'!M16+'Rekap area'!Q16+'Rekap area'!U16+'Rekap area'!Y16 -> 0.52349 | F16: ='Rekap area'!F16+'Rekap area'!J16+'Rekap area'!N16+'Rekap area'!R16+'Rekap area'!V16+'Rekap area'!Z16 -> 5.09 | G16: =SUM(D16:F16) -> 20.53939
A17: 10 | B17: April | C17: =$G$3 -> 2025 | D17: ='Rekap area'!D17+'Rekap area'!H17+'Rekap area'!L17+'Rekap area'!P17+'Rekap area'!T17+'Rekap area'!X17 -> 10.2261 | E17: ='Rekap area'!E17+'Rekap area'!I17+'Rekap area'!M17+'Rekap area'!Q17+'Rekap area'!U17+'Rekap area'!Y17 -> 0.3258 | F17: ='Rekap area'!F17+'Rekap area'!J17+'Rekap area'!N17+'Rekap area'!R17+'Rekap area'!V17+'Rekap area'!Z17 -> 0 | G17: =SUM(D17:F17) -> 10.5519
A18: 11 | B18: Mei | C18: =$G$3 -> 2025 | D18: ='Rekap area'!D18+'Rekap area'!H18+'Rekap area'!L18+'Rekap area'!P18+'Rekap area'!T18+'Rekap area'!X18 -> 9.0948 | E18: ='Rekap area'!E18+'Rekap area'!I18+'Rekap area'!M18+'Rekap area'!Q18+'Rekap area'!U18+'Rekap area'!Y18 -> 0.4562 | F18: ='Rekap area'!F18+'Rekap area'!J18+'Rekap area'!N18+'Rekap area'!R18+'Rekap area'!V18+'Rekap area'!Z18 -> 0.431 | G18: =SUM(D18:F18) -> 9.982
A19: 12 | B19: Juni | C19: =$G$3 -> 2025 | D19: ='Rekap area'!D19+'Rekap area'!H19+'Rekap area'!L19+'Rekap area'!P19+'Rekap area'!T19+'Rekap area'!X19 -> 3.0261 | E19: ='Rekap area'!E19+'Rekap area'!I19+'Rekap area'!M19+'Rekap area'!Q19+'Rekap area'!U19+'Rekap area'!Y19 -> 2.5925 | F19: ='Rekap area'!F19+'Rekap area'!J19+'Rekap area'!N19+'Rekap area'!R19+'Rekap area'!V19+'Rekap area'!Z19 -> 1.24 | G19: =SUM(D19:F19) -> 6.8586
B20: Total (ton/tahun) | D20: =SUM(D8:D19) -> 375.75614 | E20: =SUM(E8:E19) -> 35.920994 | F20: =SUM(F8:F19) -> 267.73163 | G20: =SUM(G8:G19) -> 679.40876
C22: Mengetahui, | F22: (kab/kota), tgl-bulan-tahun
C23: Jabatan Pimpinan | F23: Jabatan Penyusun
C25: ttd+cap | F25: ttd
C27: nama pimpinan | F27: nama penyusun
C28: nopeg/nip | F28: nopeg/nip

Sheet Rekap area
A1: Rekap Data Pengelolaan Sampah
A2: Berdasarkan Per Lokasi Area
A3: Periode | C3: JULI | D3: ='Rekap Neraca Pengelolaan Sampah'!D2 -> 2024 | E3: - | F3: JUNI | G3: ='Rekap Neraca Pengelolaan Sampah'!G2 -> 2025
A4: Perusahaan | C4: ='Rekap Neraca Pengelolaan Sampah'!C3 -> PT PELINDO DAYA SEJAHTERA
A6: No | B6: Bulan | C6: Tahun | D6: Area Kantor (ton/bulan) | H6: Area Tempat Parkir/Taman/Jalan (ton/bulan) | L6: Area Ruang Tunggu (ton/bulan) | P6: Area Tempat Makan (ton/bulan) | T6: Sampah kapal (khusus pelabuhan) (ton/bulan) | X6: Area Lain (ton/bulan)
D7: Jumlah Sampah Organik Terpilah | E7: Jumlah Sampah Anorganik Terpilah | F7: Jumlah Sampah Lainnya dan/atau Residu | G7: Jumlah Timbulan Sampah | H7: Jumlah Sampah Organik Terpilah | I7: Jumlah Sampah Anorganik Terpilah | J7: Jumlah Sampah Lainnya dan/atau Residu | K7: Jumlah Timbulan Sampah | L7: Jumlah Sampah Organik Terpilah | M7: Jumlah Sampah Anorganik Terpilah | N7: Jumlah Sampah Lainnya dan/atau Residu | O7: Jumlah Timbulan Sampah | P7: Jumlah Sampah Organik Terpilah | Q7: Jumlah Sampah Anorganik Terpilah | R7: Jumlah Sampah Lainnya dan/atau Residu | S7: Jumlah Timbulan Sampah | T7: Jumlah Sampah Organik Terpilah | U7: Jumlah Sampah Anorganik Terpilah | V7: Jumlah Sampah Lainnya dan/atau Residu | W7: Jumlah Timbulan Sampah | X7: Jumlah Sampah Organik Terpilah | Y7: Jumlah Sampah Anorganik Terpilah | Z7: Jumlah Sampah Lainnya dan/atau Residu | AA7: Jumlah Timbulan Sampah
A8: 1 | B8: Juli | C8: =$D$3 -> 2024 | D8: =Juli!$C$40 -> 4.518 | E8: =Juli!$D$40 -> 1.032928 | F8: =Juli!$E$40 -> 1.395 | G8: =SUM(D8:F8) -> 6.945928 | H8: =Juli!G$40 -> 20.472 | I8: =Juli!H$40 -> 0.9802 | J8: =Juli!I$40 -> 6.012 | K8: =SUM(H8:J8) -> 27.4642 | L8: =Juli!K$40 -> 5.0068 | M8: =Juli!L$40 -> 0.56784 | N8: =Juli!M$40 -> 1.829 | O8: =SUM(L8:N8) -> 7.40364 | P8: =Juli!O$40 -> 26.5076 | Q8: =Juli!P$40 -> 0.91936 | R8: =Juli!Q$40 -> 14.56 | S8: =SUM(P8:R8) -> 41.98696 | T8: =Juli!S$40 -> 2.24 | U8: =Juli!T$40 -> 1.02752 | V8: =Juli!U$40 -> 1.74 | W8: =SUM(T8:V8) -> 5.00752 | X8: =Juli!W$40 -> 0.72 | Y8: =Juli!X$40 -> 5.82712 | Z8: =Juli!Y$40 -> 1.434 | AA8: =SUM(X8:Z8) -> 7.98112
A9: 2 | B9: Agustus | C9: =$D$3 -> 2024 | D9: =Agustus!$C$40 -> 4.9396 | E9: =Agustus!$D$40 -> 0.460356 | F9: =Agustus!$E$40 -> 2.45 | G9: =SUM(D9:F9) -> 7.849956 | H9: =Agustus!G$40 -> 13.2552 | I9: =Agustus!H$40 -> 0.75036 | J9: =Agustus!I$40 -> 7.26 | K9: =SUM(H9:J9) -> 21.26556 | L9: =Agustus!K$40 -> 5.6608 | M9: =Agustus!L$40 -> 0.346112 | N9: =Agustus!M$40 -> 2.565 | O9: =SUM(L9:N9) -> 8.571912 | P9: =Agustus!O$40 -> 16.426 | Q9: =Agustus!P$40 -> 6.600464 | R9: =Agustus!Q$40 -> 13 | S9: =SUM(P9:R9) -> 36.026464 | T9: =Agustus!S$40 -> 2.32 | U9: =Agustus!T$40 -> 0.45292 | V9: =Agustus!U$40 -> 1.565 | W9: =SUM(T9:V9) -> 4.33792 | X9: =Agustus!W$40 -> 2.34 | Y9: =Agustus!X$40 -> 0.12844 | Z9: =Agustus!Y$40 -> 1.625 | AA9: =SUM(X9:Z9) -> 4.09344
A10: 3 | B10: September | C10: =$D$3 -> 2024 | D10: =September!$C$40 -> 0.2884 | E10: =September!$D$40 -> 0.14274 | F10: =September!$E$40 -> 6.145 | G10: =SUM(D10:F10) -> 6.57614 | H10: =September!G$40 -> 0.3248 | I10: =September!H$40 -> 0.19188 | J10: =September!I$40 -> 10.48 | K10: =SUM(H10:J10) -> 10.99668 | L10: =September!K$40 -> 0.458 | M10: =September!L$40 -> 0.16068 | N10: =September!M$40 -> 2.4 | O10: =SUM(L10:N10) -> 3.01868 | P10: =September!O$40 -> 0.4864 | Q10: =September!P$40 -> 0.23244 | R10: =September!Q$40 -> 18.965 | S10: =SUM(P10:R10) -> 19.68384 | T10: =September!S$40 -> 0 | U10: =September!T$40 -> 0.1508 | V10: =September!U$40 -> 3.5 | W10: =SUM(T10:V10) -> 3.6508 | X10: =September!W$40 -> 0 | Y10: =September!X$40 -> 0.9802 | Z10: =September!Y$40 -> 4.627 | AA10: =SUM(X10:Z10) -> 5.6072
A11: 4 | B11: Oktober | C11: =$D$3 -> 2024 | D11: =Oktober!$C$40 -> 0 | E11: =Oktober!$D$40 -> 0.25688 | F11: =Oktober!$E$40 -> 5.517 | G11: =SUM(D11:F11) -> 5.77388 | H11: =Oktober!G$40 -> 0.2908 | I11: =Oktober!H$40 -> 0.5096 | J11: =Oktober!I$40 -> 11.532 | K11: =SUM(H11:J11) -> 12.3324 | L11: =Oktober!K$40 -> 0.4592 | M11: =Oktober!L$40 -> 0.34528 | N11: =Oktober!M$40 -> 2.445 | O11: =SUM(L11:N11) -> 3.24948 | P11: =Oktober!O$40 -> 0.4824 | Q11: =Oktober!P$40 -> 0.66508 | R11: =Oktober!Q$40 -> 19.033 | S11: =SUM(P11:R11) -> 20.18048 | T11: =Oktober!S$40 -> 0 | U11: =Oktober!T$40 -> 0.3172 | V11: =Oktober!U$40 -> 3.063 | W11: =SUM(T11:V11) -> 3.3802 | X11: =Oktober!W$40 -> 0 | Y11: =Oktober!X$40 -> 0.4524 | Z11: =Oktober!Y$40 -> 4.093 | AA11: =SUM(X11:Z11) -> 4.5454
A12: 5 | B12: November | C12: =$D$3 -> 2024 | D12: =November!$C$40 -> 2.119 | E12: =November!$D$40 -> 0.456976 | F12: =November!$E$40 -> 3.553 | G12: =SUM(D12:F12) -> 6.128976 | H12: =November!G$40 -> 12.1788 | I12: =November!H$40 -> 0.600964 | J12: =November!I$40 -> 6.77 | K12: =SUM(H12:J12) -> 19.549764 | L12: =November!K$40 -> 3.928 | M12: =November!L$40 -> 0.323128 | N12: =November!M$40 -> 1.66 | O12: =SUM(L12:N12) -> 5.911128 | P12: =November!O$40 -> 21.758 | Q12: =November!P$40 -> 0.673296 | R12: =November!Q$40 -> 14.27 | S12: =SUM(P12:R12) -> 36.701296 | T12: =November!S$40 -> 4.452 | U12: =November!T$40 -> 0.37856 | V12: =November!U$40 -> 1.84 | W12: =SUM(T12:V12) -> 6.67056 | X12: =November!W$40 -> 5.46 | Y12: =November!X$40 -> 0.2366 | Z12: =November!Y$40 -> 1.8 | AA12: =SUM(X12:Z12) -> 7.4966
A13: 6 | B13: Desember | C13: =$D$3 -> 2024 | D13: =Desember!$C$40 -> 6.24 | E13: =Desember!$D$40 -> 0.30212 | F13: =Desember!$E$40 -> 2.663 | G13: =SUM(D13:F13) -> 9.20512 | H13: =Desember!G$40 -> 20.3092 | I13: =Desember!H$40 -> 0.39208 | J13: =Desember!I$40 -> 11.1 | K13: =SUM(H13:J13) -> 31.80128 | L13: =Desember!K$40 -> 7.746 | M13: =Desember!L$40 -> 0.36088 | N13: =Desember!M$40 -> 2.25 | O13: =SUM(L13:N13) -> 10.35688 | P13: =Desember!O$40 -> 28.68124 | Q13: =Desember!P$40 -> 0.59644 | R13: =Desember!Q$40 -> 12.2 | S13: =SUM(P13:R13) -> 41.47768 | T13: =Desember!S$40 -> 27.024 | U13: =Desember!T$40 -> 0.104 | V13: =Desember!U$40 -> 15.831 | W13: =SUM(T13:V13) -> 42.959 | X13: =Desember!W$40 -> 5.808 | Y13: =Desember!X$40 -> 0.1664 | Z13: =Desember!Y$40 -> 1.518 | AA13: =SUM(X13:Z13) -> 7.4924
A14: 7 | B14: Januari | C14: =$G$3 -> 2025 | D14: =Januari!$C$40 -> 3.644 | E14: =Januari!$D$40 -> 0.26624 | F14: =Januari!$E$40 -> 4.93 | G14: =SUM(D14:F14) -> 8.84024 | H14: =Januari!G$40 -> 6.8088 | I14: =Januari!H$40 -> 0.3926 | J14: =Januari!I$40 -> 4.024228 | K14: =SUM(H14:J14) -> 11.225628 | L14: =Januari!K$40 -> 2.5376 | M14: =Januari!L$40 -> 0.32188 | N14: =Januari!M$40 -> 3.5405 | O14: =SUM(L14:N14) -> 6.39998 | P14: =Januari!O$40 -> 1.9108 | Q14: =Januari!P$40 -> 0.53092 | R14: =Januari!Q$40 -> 6.4009 | S14: =SUM(P14:R14) -> 8.84262 | T14: =Januari!S$40 -> 0 | U14: =Januari!T$40 -> 0.3068 | V14: =Januari!U$40 -> 4.045 | W14: =SUM(T14:V14) -> 4.3518 | X14: =Januari!W$40 -> 1.9 | Y14: =Januari!X$40 -> 0.2184 | Z14: =Januari!Y$40 -> 2.84 | AA14: =SUM(X14:Z14) -> 4.9584
A15: 8 | B15: Februari | C15: =$G$3 -> 2025 | D15: =Februari!$C$40 -> 6.944 | E15: =Februari!$D$40 -> 0.39156 | F15: =Februari!$E$40 -> 0 | G15: =SUM(D15:F15) -> 7.33556 | H15: =Februari!G$40 -> 21.3628 | I15: =Februari!H$40 -> 0.37544 | J15: =Februari!I$40 -> 5 | K15: =SUM(H15:J15) -> 26.73824 | L15: =Februari!K$40 -> 0.3196 | M15: =Februari!L$40 -> 0.28184 | N15: =Februari!M$40 -> 0 | O15: =SUM(L15:N15) -> 0.60144 | P15: =Februari!O$40 -> 30.3554 | Q15: =Februari!P$40 -> 0.41028 | R15: =Februari!Q$40 -> 7.5 | S15: =SUM(P15:R15) -> 38.26568 | T15: =Februari!S$40 -> 6.16 | U15: =Februari!T$40 -> 0.2704 | V15: =Februari!U$40 -> 0 | W15: =SUM(T15:V15) -> 6.4304 | X15: =Februari!W$40 -> 3.64 | Y15: =Februari!X$40 -> 0.1664 | Z15: =Februari!Y$40 -> 0 | AA15: =SUM(X15:Z15) -> 3.8064
A16: 9 | B16: Maret | C16: =$G$3 -> 2025 | D16: =Maret!$C$40 -> 4.81 | E16: =Maret!$D$40 -> 0.09299 | F16: =Maret!$E$40 -> 1.03 | G16: =SUM(D16:F16) -> 5.93299 | H16: =Maret!G$40 -> 1.5119 | I16: =Maret!H$40 -> 0.0606 | J16: =Maret!I$40 -> 1.2 | K16: =SUM(H16:J16) -> 2.7725 | L16: =Maret!K$40 -> 0.0719 | M16: =Maret!L$40 -> 0.1047 | N16: =Maret!M$40 -> 0.5 | O16: =SUM(L16:N16) -> 0.6766 | P16: =Maret!O$40 -> 6.7321 | Q16: =Maret!P$40 -> 0.0922 | R16: =Maret!Q$40 -> 1.48 | S16: =SUM(P16:R16) -> 8.3043 | T16: =Maret!S$40 -> 1.18 | U16: =Maret!T$40 -> 0.055 | V16: =Maret!U$40 -> 0.464 | W16: =SUM(T16:V16) -> 1.699 | X16: =Maret!W$40 -> 0.62 | Y16: =Maret!X$40 -> 0.118 | Z16: =Maret!Y$40 -> 0.416 | AA16: =SUM(X16:Z16) -> 1.154
A17: 10 | B17: April | C17: =$G$3 -> 2025 | D17: =April!$C$40 -> 1.399 | E17: =April!$D$40 -> 0.094 | F17: =April!$E$40 -> 0 | G17: =SUM(D17:F17) -> 1.493 | H17: =April!G$40 -> 2.1673 | I17: =April!H$40 -> 0.0448 | J17: =April!I$40 -> 0 | K17: =SUM(H17:J17) -> 2.2121 | L17: =April!K$40 -> 0.0898 | M17: =April!L$40 -> 0.0427 | N17: =April!M$40 -> 0 | O17: =SUM(L17:N17) -> 0.1325 | P17: =April!O$40 -> 2.96 | Q17: =April!P$40 -> 0.0713 | R17: =April!Q$40 -> 0 | S17: =SUM(P17:R17) -> 3.0313 | T17: =April!S$40 -> 2.705 | U17: =April!T$40 -> 0.049 | V17: =April!U$40 -> 0 | W17: =SUM(T17:V17) -> 2.754 | X17: =April!W$40 -> 0.905 | Y17: =April!X$40 -> 0.024 | Z17: =April!Y$40 -> 0 | AA17: =SUM(X17:Z17) -> 0.929
A18: 11 | B18: Mei | C18: =$G$3 -> 2025 | D18: =Mei!$C$40 -> 1.58 | E18: =Mei!$D$40 -> 0.0643 | F18: =Mei!$E$40 -> 0.033 | G18: =SUM(D18:F18) -> 1.6773 | H18: =Mei!G$40 -> 0.6402 | I18: =Mei!H$40 -> 0.0953 | J18: =Mei!I$40 -> 0.08 | K18: =SUM(H18:J18) -> 0.8155 | L18: =Mei!K$40 -> 0.0662 | M18: =Mei!L$40 -> 0.062 | N18: =Mei!M$40 -> 0.1 | O18: =SUM(L18:N18) -> 0.2282 | P18: =Mei!O$40 -> 3.0384 | Q18: =Mei!P$40 -> 0.1176 | R18: =Mei!Q$40 -> 0.13 | S18: =SUM(P18:R18) -> 3.286 | T18: =Mei!S$40 -> 2.58 | U18: =Mei!T$40 -> 0.085 | V18: =Mei!U$40 -> 0.029 | W18: =SUM(T18:V18) -> 2.694 | X18: =Mei!W$40 -> 1.19 | Y18: =Mei!X$40 -> 0.032 | Z18: =Mei!Y$40 -> 0.059 | AA18: =SUM(X18:Z18) -> 1.281
A19: 12 | B19: Juni | C19: =$G$3 -> 2025 | D19: =Juni!$C$40 -> 0.6405 | E19: =Juni!$D$40 -> 0.4562 | F19: =Juni!$E$40 -> 0.12 | G19: =SUM(D19:F19) -> 1.2167 | H19: =Juni!G$40 -> 0.6518 | I19: =Juni!H$40 -> 0.6082 | J19: =Juni!I$40 -> 0.4 | K19: =SUM(H19:J19) -> 1.66 | L19: =Juni!K$40 -> 0.9044 | M19: =Juni!L$40 -> 0.1546 | N19: =Juni!M$40 -> 0.2 | O19: =SUM(L19:N19) -> 1.259 | P19: =Juni!O$40 -> 0.7394 | Q19: =Juni!P$40 -> 0.3585 | R19: =Juni!Q$40 -> 0.4 | S19: =SUM(P19:R19) -> 1.4979 | T19: =Juni!S$40 -> 0 | U19: =Juni!T$40 -> 0.295 | V19: =Juni!U$40 -> 0.02 | W19: =SUM(T19:V19) -> 0.315 | X19: =Juni!W$40 -> 0.09 | Y19: =Juni!X$40 -> 0.72 | Z19: =Juni!Y$40 -> 0.1 | AA19: =SUM(X19:Z19) -> 0.91
A20: Total (ton/tahun) | D20: =SUM(D8:D19) -> 37.1225 | E20: =SUM(E8:E19) -> 4.01729 | F20: =SUM(F8:F19) -> 27.836 | G20: =SUM(G8:G19) -> 68.97579 | H20: =SUM(H8:H19) -> 99.9736 | I20: =SUM(I8:I19) -> 5.002024 | J20: =SUM(J8:J19) -> 63.858228 | K20: =SUM(K8:K19) -> 168.83385 | ... AA20: =SUM(AA8:AA19) -> 50.25496
D22: Mengetahui, | V22: (kab/kota), tgl-bulan-tahun
D23: Jabatan Pimpinan | V23: Jabatan Penyusun
D25: ttd+cap | V25: ttd
D27: nama pimpinan | V27: nama penyusun
D28: nopeg/nip | V28: nopeg/nip

Sheet Juli
A1: Perusahaan : | B1: ='Rekap Neraca Pengelolaan Sampah'!C3 -> PT PELINDO DAYA SEJAHTERA
A2: Tahun | B2: ='Rekap Neraca Pengelolaan Sampah'!D2 -> 2024
A3: Bulan: | B3: Juli | C3: REKAMAN TIMBULAN SAMPAH | G3: REKAMAN TIMBULAN SAMPAH | K3: REKAMAN TIMBULAN SAMPAH | O3: REKAMAN TIMBULAN SAMPAH | S3: REKAMAN TIMBULAN SAMPAH | W3: REKAMAN TIMBULAN SAMPAH | AA3: TOTAL TIMBULAN SAMPAH DI SELURUH AREA | AB3: Satuan | AD3: REKAMAN REKAP JUMLAH SAMPAH BERDASARKAN | AJ3: REKAMAN REKAP JUMLAH PENGELOLAAN SAMPAH
A4: No | B4: Tanggal | C4: (kg/hari) | G4: (kg/hari) | K4: (kg/hari) | O4: (kg/hari) | S4: (kg/hari) | W4: (kg/hari) | AD4: JENIS SAMPAH TERPILAH | AJ4: DI SELURUH AREA
C5: Sumber sampah | G5: Sumber sampah | K5: Sumber sampah | O5: Sumber sampah | S5: Sumber sampah | W5: Sumber sampah | AD5: (kg/hari) | AJ5: Bulan : | AK5: =B3 -> Juli | AL5: Tahun : | AM5: =#REF! -> #REF!
C6: Area Kantor | G6: Area Tempat Parkir/Taman/Jalan | K6: Area Ruang Tunggu | O6: Area Tempat Makan | S6: Sampah Kapal (Khusus Pelabuhan) | W6: Area Lain (sebutkan jika ada) | AD6: Bulan : | AE6: =B3 -> Juli | AF6: Tahun : | AG6: =#REF! -> #REF! | AJ6: Sampah Terkelola (kg/hari)
C7: Sampah Organik Terpilah | D7: Sampah Anorganik Terpilah | E7: Sampah Lainnya dan/atau Residu | F7: Total Timbulan Sampah | G7: Sampah Organik Terpilah | H7: Sampah Anorganik Terpilah | I7: Sampah Lainnya dan/atau Residu | J7: Total Timbulan Sampah | K7: Sampah Organik Terpilah | L7: Sampah Anorganik Terpilah | M7: Sampah Lainnya dan/atau Residu | N7: Total Timbulan Sampah | O7: Sampah Organik Terpilah | P7: Sampah Anorganik Terpilah | Q7: Sampah Lainnya dan/atau Residu | R7: Total Timbulan Sampah | S7: Sampah Organik Terpilah | T7: Sampah Anorganik Terpilah | U7: Sampah Lainnya dan/atau Residu | V7: Total Timbulan Sampah | W7: Sampah Organik Terpilah | X7: Sampah Anorganik Terpilah | Y7: Sampah Lainnya dan/atau Residu | Z7: Total Timbulan Sampah | AD7: No. | AE7: Tanggal | AF7: Jumlah Sampah Organik | AG7: Jumlah Sampah Anorganik | AH7: Jumlah Sampah Residu ke TPA | AJ7: No. | AK7: Tanggal | AL7: Kompos / Pakan Ternak | AM7: Prosentase Kompos/pakan ternak | AN7: Bank Sampah / TPS3R / PDU | AO7: Prosentase Bank Sampah / TPS3R / PDU | AP7: Sampah Residu yang diangkut ke TPA | AQ7: Prosentase Sampah Residu yang diangkut ke TPA
A8: 1 | B8: 01 | C8: 222.8 | D8: =(((((2.2+2)*1.3)*1.3)*2)*2)*2 -> 56.784 | E8: 120 | F8: =SUM(C8:E8) -> 399.584 | G8: 817.2 | H8: =(((((3.7+3)*1.3)*1.3)*2)*2)*2 -> 90.584 | I8: 250 | J8: =SUM(G8:I8) -> 1157.784 | K8: 18 | L8: 16.224 | N8: =SUM(K8:M8) -> 34.224 | O8: 816.4 | P8: =(((((4.6+1)*1.3)*1.3)*2)*2)*2 -> 75.712 | Q8: 400 | R8: =SUM(O8:Q8) -> 1292.112 | S8: 160 | T8: =(((((2+3)*1.3)*1.3)*2)*2)*2 -> 67.6 | U8: 100 | V8: =SUM(S8:U8) -> 327.6 | W8: 0 | X8: =(((((23+1)*1.3)*1.3)*2)*2)*2 -> 324.48 | Y8: 47 | Z8: =SUM(W8:Y8) -> 371.48 | AA8: =(F8+J8+N8+R8+V8+Z8) -> 3582.784 | AB8: kg/hari | AD8: 1 | AE8: 01 | AF8: =(C8+G8+K8+O8+S8+W8) -> 2034.4 | AG8: =(D8+H8+L8+P8+T8+X8) -> 631.384 | AH8: =(E8+I8+M8+Q8++U8+Y8) -> 917 | AJ8: 1 | AK8: 01 | AL8: =AF8 -> 2034.4 | AM8: =AL8/AA8 -> 0.56782658 | AN8: =AG8 -> 631.384 | AO8: =AN8/AA8 -> 0.1762272 | AP8: =AH8 -> 917 | AQ8: =AP8/AA8 -> 0.25594621
A9: 2 | B9: 02 | C9: 218 | D9: 29.744 | E9: 50 | F9: =SUM(C9:E9) -> 297.744 | G9: 1014.4 | H9: 48.672 | I9: 250 | J9: =SUM(G9:I9) -> 1313.072 | K9: 14 | L9: 10.816 | N9: =SUM(K9:M9) -> 24.816 | O9: 2021.6 | P9: 89.232 | Q9: 610 | R9: =SUM(O9:Q9) -> 2720.832 | S9: 120 | T9: =(((((2+1)*1.3)*1.3)*2)*2)*2 -> 40.56 | U9: 100 | V9: =SUM(S9:U9) -> 260.56 | W9: 200 | X9: 310.96 | Y9: 156 | Z9: =SUM(W9:Y9) -> 666.96 | AA9: =(F9+J9+N9+R9+V9+Z9) -> 5283.984 | AB9: kg/hari | AD9: 2 | AE9: 02 | AF9: =(C9+G9+K9+O9+S9+W9) -> 3588 | AG9: =(D9+H9+L9+P9+T9+X9) -> 529.984 | AH9: =(E9+I9+M9+Q9++U9+Y9) -> 1166 | AJ9: 2 | AK9: 02 | AL9: =AF9 -> 3588 | AM9: =AL9/AA9 -> 0.67903309 | AN9: =AG9 -> 529.984 | AO9: =AN9/AA9 -> 0.10030008 | AP9: =AH9 -> 1166 | AQ9: =AP9/AA9 -> 0.22066683
A10: 3 | B10: 03 | C10: 224.4 | D10: =(((((3.1+2)*1.3)*1.3)*2)*2)*2 -> 68.952 | E10: 135 | F10: =SUM(C10:E10) -> 428.352 | G10: 1015.6 | H10: =(((((4.3+2)*1.3)*1.3)*2)*2)*2 -> 85.176 | I10: 300 | J10: =SUM(G10:I10) -> 1400.776 | K10: 11.6 | L10: 14.872 | N10: =SUM(K10:M10) -> 26.472 | O10: 2012.8 | P10: =(((((1.8+1)*1.3)*1.3)*2)*2)*2 -> 37.856 | Q10: 500 | R10: =SUM(O10:Q10) -> 2550.656 | S10: 80 | T10: =(((((2+3)*1.3)*1.3)*2)*2)*2 -> 67.6 | U10: 85 | V10: =SUM(S10:U10) -> 232.6 | W10: 60 | X10: 297.44 | Y10: 115 | Z10: =SUM(W10:Y10) -> 472.44 | AA10: =(F10+J10+N10+R10+V10+Z10) -> 5111.296 | AB10: kg/hari | AD10: 3 | AE10: 03 | AF10: =(C10+G10+K10+O10+S10+W10) -> 3404.4 | AG10: =(D10+H10+L10+P10+T10+X10) -> 571.896 | AH10: =(E10+I10+M10+Q10++U10+Y10) -> 1135 | AJ10: 3 | AK10: 03 | AL10: =AF10 -> 3404.4 | AM10: =AL10/AA10 -> 0.66605417 | AN10: =AG10 -> 571.896 | AO10: =AN10/AA10 -> 0.11188865 | AP10: =AH10 -> 1135 | AQ10: =AP10/AA10 -> 0.22205718
A11: 4 | B11: 04 | C11: 218.8 | D11: 31.096 | E11: 110 | F11: =SUM(C11:E11) -> 359.896 | G11: 816.8 | H11: =(((((3.2+1)*1.3)*1.3)*2)*2)*2 -> 56.784 | I11: 270 | J11: =SUM(G11:I11) -> 1143.584 | K11: 212 | L11: 9.464 | M11: 45 | N11: =SUM(K11:M11) -> 266.464 | O11: 1214.4 | P11: 25.688 | Q11: 570 | R11: =SUM(O11:Q11) -> 1810.088 | S11: 80 | T11: =(((((2+2)*1.3)*1.3)*2)*2)*2 -> 54.08 | U11: 60 | V11: =SUM(S11:U11) -> 194.08 | W11: 0 | X11: 297.44 | Y11: 45 | Z11: =SUM(W11:Y11) -> 342.44 | AA11: =(F11+J11+N11+R11+V11+Z11) -> 4116.552 | AB11: kg/hari | AD11: 4 | AE11: 04 | AF11: =(C11+G11+K11+O11+S11+W11) -> 2542 | AG11: =(D11+H11+L11+P11+T11+X11) -> 474.552 | AH11: =(E11+I11+M11+Q11++U11+Y11) -> 1100 | AJ11: 4 | AK11: 04 | AL11: =AF11 -> 2542 | AM11: =AL11/AA11 -> 0.61750708 | AN11: =AG11 -> 474.552 | AO11: =AN11/AA11 -> 0.115279 | AP11: =AH11 -> 1100 | AQ11: =AP11/AA11 -> 0.26721392
A12: 5 | B12: 05 | C12: 216.4 | D12: =(((((2+1)*1.3)*1.3)*2)*2)*2 -> 40.56 | E12: 15 | F12: =SUM(C12:E12) -> 271.96 | G12: 420.4 | H12: 35.152 | I12: 100 | J12: =SUM(G12:I12) -> 555.552 | K12: 14.4 | L12: 32.448 | N12: =SUM(K12:M12) -> 46.848 | O12: 417.2 | P12: 27.04 | Q12: 300 | R12: =SUM(O12:Q12) -> 744.24 | S12: 60 | T12: =(((((2+2)*1.3)*1.3)*2)*2)*2 -> 54.08 | U12: 60 | V12: =SUM(S12:U12) -> 174.08 | W12: 0 | X12: =(((((22+1)*1.3)*1.3)*2)*2)*2 -> 310.96 | Y12: 40 | Z12: =SUM(W12:Y12) -> 350.96 | AA12: =(F12+J12+N12+R12+V12+Z12) -> 2143.64 | AB12: kg/hari | AD12: 5 | AE12: 05 | AF12: =(C12+G12+K12+O12+S12+W12) -> 1128.4 | AG12: =(D12+H12+L12+P12+T12+X12) -> 500.24 | AH12: =(E12+I12+M12+Q12++U12+Y12) -> 515 | AJ12: 5 | AK12: 05 | AL12: =AF12 -> 1128.4 | AM12: =AL12/AA12 -> 0.52639436 | AN12: =AG12 -> 500.24 | AO12: =AN12/AA12 -> 0.23336008 | AP12: =AH12 -> 515 | AQ12: =AP12/AA12 -> 0.24024556
A13: 6 | B13: 06 | C13: 200 | D13: 0 | E13: 20 | F13: =SUM(C13:E13) -> 220 | G13: 720 | H13: 0 | I13: 200 | J13: =SUM(G13:I13) -> 920 | K13: 0 | L13: 0 | N13: =SUM(K13:M13) -> 0 | O13: 800 | P13: 0 | Q13: 370 | R13: =SUM(O13:Q13) -> 1170 | S13: 100 | T13: =(((((1+2)*1.3)*1.3)*2)*2)*2 -> 40.56 | U13: 65 | V13: =SUM(S13:U13) -> 205.56 | W13: 0 | X13: 283.92 | Y13: 20 | Z13: =SUM(W13:Y13) -> 303.92 | AA13: =(F13+J13+N13+R13+V13+Z13) -> 2819.48 | AB13: kg/hari | AD13: 6 | AE13: 06 | AF13: =(C13+G13+K13+O13+S13+W13) -> 1820 | AG13: =(D13+H13+L13+P13+T13+X13) -> 324.48 | AH13: =(E13+I13+M13+Q13++U13+Y13) -> 675 | AJ13: 6 | AK13: 06 | AL13: =AF13 -> 1820 | AM13: =AL13/AA13 -> 0.6455091 | AN13: =AG13 -> 324.48 | AO13: =AN13/AA13 -> 0.11508505 | AP13: =AH13 -> 675 | AQ13: =AP13/AA13 -> 0.23940585
A14: 7 | B14: 07 | C14: 0 | D14: 0 | E14: =[1]Juli!O12+[2]Juli!O12+[3]Juli!O12 -> 0 | F14: =SUM(C14:E14) -> 0 | G14: 0 | H14: 0 | I14: =[2]Juli!V12+[1]Juli!V12+[3]Juli!V12 -> 0 | J14: =SUM(G14:I14) -> 0 | K14: 0 | L14: 0 | N14: =SUM(K14:M14) -> 0 | O14: 0 | P14: 0 | Q14: 0 | R14: =SUM(O14:Q14) -> 0 | S14: 0 | T14: 0 | V14: =SUM(S14:U14) -> 0 | W14: 0 | X14: 0 | Y14: 0 | Z14: =SUM(W14:Y14) -> 0 | AA14: =(F14+J14+N14+R14+V14+Z14) -> 0 | AB14: kg/hari | AD14: 7 | AE14: 07 | AF14: =(C14+G14+K14+O14+S14+W14) -> 0 | AG14: =(D14+H14+L14+P14+T14+X14) -> 0 | AH14: =(E14+I14+M14+Q14++U14+Y14) -> 0 | AJ14: 7 | AK14: 07 | AL14: =AF14 -> 0 | AM14: =AL14/AA14 -> #DIV/0! | AN14: =AG14 -> 0 | AO14: =AN14/AA14 -> #DIV/0! | AP14: =AH14 -> 0 | AQ14: =AP14/AA14 -> #DIV/0!
A15: 8 | B15: 08 | C15: 215.6 | D15: =(((((2.1+1)*1.3)*1.3)*2)*2)*2 -> 41.912 | E15: 140 | F15: =SUM(C15:E15) -> 397.512 | G15: 1614 | H15: =(((((3.2+2)*1.3)*1.3)*2)*2)*2 -> 70.304 | I15: 560 | J15: =SUM(G15:I15) -> 2244.304 | K15: 91.2 | L15: 16.224 | M15: 50 | N15: =SUM(K15:M15) -> 157.424 | O15: 1618.8 | P15: =(((((4.4+1)*1.3)*1.3)*2)*2)*2 -> 73.008 | Q15: 1200 | R15: =SUM(O15:Q15) -> 2891.808 | S15: 80 | T15: =(((((2+2)*1.3)*1.3)*2)*2)*2 -> 54.08 | U15: 70 | V15: =SUM(S15:U15) -> 204.08 | W15: 120 | X15: 297.44 | Y15: 200 | Z15: =SUM(W15:Y15) -> 617.44 | AA15: =(F15+J15+N15+R15+V15+Z15) -> 6512.568 | AB15: kg/hari | AD15: 8 | AE15: 08 | AF15: =(C15+G15+K15+O15+S15+W15) -> 3739.6 | AG15: =(D15+H15+L15+P15+T15+X15) -> 552.968 | AH15: =(E15+I15+M15+Q15++U15+Y15) -> 2220 | AJ15: 8 | AK15: 08 | AL15: =AF15 -> 3739.6 | AM15: =AL15/AA15 -> 0.57421281 | AN15: =AG15 -> 552.968 | AO15: =AN15/AA15 -> 0.084907827 | AP15: =AH15 -> 2220 | AQ15: =AP15/AA15 -> 0.34087936
A16: 9 | B16: 09 | C16: 216.8 | D16: 24.336 | E16: 85 | F16: =SUM(C16:E16) -> 326.136 | G16: 819.6 | H16: 63.544 | I16: 140 | J16: =SUM(G16:I16) -> 1023.144 | K16: 410.8 | L16: 17.576 | M16: 110 | N16: =SUM(K16:M16) -> 538.376 | O16: 822.4 | P16: 52.728 | Q16: 300 | R16: =SUM(O16:Q16) -> 1175.128 | S16: 60 | T16: =(((((2+1)*1.3)*1.3)*2)*2)*2 -> 40.56 | U16: 80 | V16: =SUM(S16:U16) -> 180.56 | W16: 0 | X16: 297.44 | Y16: 45 | Z16: =SUM(W16:Y16) -> 342.44 | AA16: =(F16+J16+N16+R16+V16+Z16) -> 3585.784 | AB16: kg/hari | AD16: 9 | AE16: 09 | AF16: =(C16+G16+K16+O16+S16+W16) -> 2329.6 | AG16: =(D16+H16+L16+P16+T16+X16) -> 496.184 | AH16: =(E16+I16+M16+Q16++U16+Y16) -> 760 | AJ16: 9 | AK16: 09 | AL16: =AF16 -> 2329.6 | AM16: =AL16/AA16 -> 0.64967661 | AN16: =AG16 -> 496.184 | AO16: =AN16/AA16 -> 0.13837532 | AP16: =AH16 -> 760 | AQ16: =AP16/AA16 -> 0.21194807
A17: 10 | B17: 10 | C17: 178.8 | D17: =(((((4.4+2)*1.3)*1.3)*2)*2)*2 -> 86.528 | E17: 40 | F17: =SUM(C17:E17) -> 305.328 | G17: 420.8 | H17: =(((((1.8+2)*1.3)*1.3)*2)*2)*2 -> 51.376 | I17: 120 | J17: =SUM(G17:I17) -> 592.176 | K17: 412.4 | L17: 13.52 | M17: 115 | N17: =SUM(K17:M17) -> 540.92 | O17: 1212.4 | P17: =(((((0.8+1)*1.3)*1.3)*2)*2)*2 -> 24.336 | Q17: 420 | R17: =SUM(O17:Q17) -> 1656.736 | S17: 80 | T17: =(((((2+3)*1.3)*1.3)*2)*2)*2 -> 67.6 | U17: 80 | V17: =SUM(S17:U17) -> 227.6 | W17: 0 | X17: 297.44 | Y17: 30 | Z17: =SUM(W17:Y17) -> 327.44 | AA17: =(F17+J17+N17+R17+V17+Z17) -> 3650.2 | AB17: kg/hari | AD17: 10 | AE17: 10 | AF17: =(C17+G17+K17+O17+S17+W17) -> 2304.4 | AG17: =(D17+H17+L17+P17+T17+X17) -> 540.8 | AH17: =(E17+I17+M17+Q17++U17+Y17) -> 805 | AJ17: 10 | AK17: 10 | AL17: =AF17 -> 2304.4 | AM17: =AL17/AA17 -> 0.63130787 | AN17: =AG17 -> 540.8 | AO17: =AN17/AA17 -> 0.14815627 | AP17: =AH17 -> 805 | AQ17: =AP17/AA17 -> 0.22053586
A18: 11 | B18: 11 | C18: 172.4 | D18: 21.632 | E18: 35 | F18: =SUM(C18:E18) -> 229.032 | G18: 816.8 | H18: 32.448 | I18: 200 | J18: =SUM(G18:I18) -> 1049.248 | K18: 412.8 | L18: 28.392 | M18: 200 | N18: =SUM(K18:M18) -> 641.192 | O18: 815.6 | P18: =(((((1.4+1)*1.3)*1.3)*2)*2)*2 -> 32.448 | Q18: 300 | R18: =SUM(O18:Q18) -> 1148.048 | S18: 60 | T18: =(((((2+2)*1.3)*1.3)*2)*2)*2 -> 54.08 | U18: 70 | V18: =SUM(S18:U18) -> 184.08 | W18: 120 | X18: 297.44 | Y18: 130 | Z18: =SUM(W18:Y18) -> 547.44 | AA18: =(F18+J18+N18+R18+V18+Z18) -> 3799.04 | AB18: kg/hari | AD18: 11 | AE18: 11 | AF18: =(C18+G18+K18+O18+S18+W18) -> 2397.6 | AG18: =(D18+H18+L18+P18+T18+X18) -> 466.44 | AH18: =(E18+I18+M18+Q18++U18+Y18) -> 935 | AJ18: 11 | AK18: 11 | AL18: =AF18 -> 2397.6 | AM18: =AL18/AA18 -> 0.63110681 | AN18: =AG18 -> 466.44 | AO18: =AN18/AA18 -> 0.12277839 | AP18: =AH18 -> 935 | AQ18: =AP18/AA18 -> 0.24611481
A19: 12 | B19: 12 | C19: 214.8 | D19: =(((((3.4+2)*1.3)*1.3)*2)*2)*2 -> 73.008 | E19: 65 | F19: =SUM(C19:E19) -> 352.808 | G19: 813.2 | H19: =(((((4.8+1)*1.3)*1.3)*2)*2)*2 -> 78.416 | I19: 350 | J19: =SUM(G19:I19) -> 1241.616 | K19: 211.6 | L19: 50.024 | M19: 50 | N19: =SUM(K19:M19) -> 311.624 | O19: 1216 | P19: =(((((0.7+1)*1.3)*1.3)*2)*2)*2 -> 22.984 | Q19: 600 | R19: =SUM(O19:Q19) -> 1838.984 | S19: 80 | T19: =(((((2+2)*1.3)*1.3)*2)*2)*2 -> 54.08 | U19: 90 | V19: =SUM(S19:U19) -> 224.08 | W19: 0 | X19: =(((((22+1)*1.3)*1.3)*2)*2)*2 -> 310.96 | Y19: 55 | Z19: =SUM(W19:Y19) -> 365.96 | AA19: =(F19+J19+N19+R19+V19+Z19) -> 4335.072 | AB19: kg/hari | AD19: 12 | AE19: 12 | AF19: =(C19+G19+K19+O19+S19+W19) -> 2535.6 | AG19: =(D19+H19+L19+P19+T19+X19) -> 589.472 | AH19: =(E19+I19+M19+Q19++U19+Y19) -> 1210 | AJ19: 12 | AK19: 12 | AL19: =AF19 -> 2535.6 | AM19: =AL19/AA19 -> 0.58490378 | AN19: =AG19 -> 589.472 | AO19: =AN19/AA19 -> 0.13597744 | AP19: =AH19 -> 1210 | AQ19: =AP19/AA19 -> 0.27911878
A20: 13 | B20: 13 | C20: 80 | D20: 0 | E20: 10 | F20: =SUM(C20:E20) -> 90 | G20: 200 | H20: 0 | I20: 30 | J20: =SUM(G20:I20) -> 230 | K20: 0 | L20: 0 | N20: =SUM(K20:M20) -> 0 | O20: 0 | P20: 0 | Q20: =[2]Juli!AC18+[1]Juli!AC18+[3]Juli!AC18 -> 180 | R20: =SUM(O20:Q20) -> 180 | S20: 40 | T20: 0 | U20: 20 | V20: =SUM(S20:U20) -> 60 | W20: 0 | X20: 0 | Y20: 30 | Z20: =SUM(W20:Y20) -> 30 | AA20: =(F20+J20+N20+R20+V20+Z20) -> 590 | AB20: kg/hari | AD20: 13 | AE20: 13 | AF20: =(C20+G20+K20+O20+S20+W20) -> 320 | AG20: =(D20+H20+L20+P20+T20+X20) -> 0 | AH20: =(E20+I20+M20+Q20++U20+Y20) -> 270 | AJ20: 13 | AK20: 13 | AL20: =AF20 -> 320 | AM20: =AL20/AA20 -> 0.54237288 | AN20: =AG20 -> 0 | AO20: =AN20/AA20 -> 0 | AP20: =AH20 -> 270 | AQ20: =AP20/AA20 -> 0.45762712
A21: 14 | B21: 14 | C21: 0 | D21: 13.52 | E21: 0 | F21: =SUM(C21:E21) -> 13.52 | G21: 0 | H21: 27.04 | I21: 0 | J21: =SUM(G21:I21) -> 27.04 | K21: 0 | L21: 0 | N21: =SUM(K21:M21) -> 0 | O21: 0 | P21: 0 | Q21: =[2]Juli!AC19+[1]Juli!AC19+[3]Juli!AC19 -> 0 | R21: =SUM(O21:Q21) -> 0 | S21: 0 | T21: 0 | V21: =SUM(S21:U21) -> 0 | W21: 0 | X21: 0 | Y21: 0 | Z21: =SUM(W21:Y21) -> 0 | AA21: =(F21+J21+N21+R21+V21+Z21) -> 40.56 | AB21: kg/hari | AD21: 14 | AE21: 14 | AF21: =(C21+G21+K21+O21+S21+W21) -> 0 | AG21: =(D21+H21+L21+P21+T21+X21) -> 40.56 | AH21: =(E21+I21+M21+Q21++U21+Y21) -> 0 | AJ21: 14 | AK21: 14 | AL21: =AF21 -> 0 | AM21: =AL21/AA21 -> 0 | AN21: =AG21 -> 40.56 | AO21: =AN21/AA21 -> 1 | AP21: =AH21 -> 0 | AQ21: =AP21/AA21 -> 0
A22: 15 | B22: 15 | C22: 100.4 | D22: 9.464 | E22: 10 | F22: =SUM(C22:E22) -> 119.864 | G22: 416.4 | H22: 28.392 | I22: 80 | J22: =SUM(G22:I22) -> 524.792 | K22: 210.8 | L22: 48.672 | M22: 140 | N22: =SUM(K22:M22) -> 399.472 | O22: 420.8 | P22: =(((((4.8+1)*1.3)*1.3)*2)*2)*2 -> 78.416 | Q22: 180 | R22: =SUM(O22:Q22) -> 679.216 | S22: 40 | T22: 40.56 | U22: 20 | V22: =SUM(S22:U22) -> 100.56 | W22: 0 | X22: 270.4 | Y22: 20 | Z22: =SUM(W22:Y22) -> 290.4 | AA22: =(F22+J22+N22+R22+V22+Z22) -> 2114.304 | AB22: kg/hari | AD22: 15 | AE22: 15 | AF22: =(C22+G22+K22+O22+S22+W22) -> 1188.4 | AG22: =(D22+H22+L22+P22+T22+X22) -> 475.904 | AH22: =(E22+I22+M22+Q22++U22+Y22) -> 450 | AJ22: 15 | AK22: 15 | AL22: =AF22 -> 1188.4 | AM22: =AL22/AA22 -> 0.56207622 | AN22: =AG22 -> 475.904 | AO22: =AN22/AA22 -> 0.22508778 | AP22: =AH22 -> 450 | AQ22: =AP22/AA22 -> 0.212836
A23: 16 | B23: 16 | C23: 176.8 | D23: =(((((0.8+2)*1.3)*1.3)*2)*2)*2 -> 37.856 | E23: 30 | F23: =SUM(C23:E23) -> 244.656 | G23: 1021.2 | H23: =(((((0.7+1)*1.3)*1.3)*2)*2)*2 -> 22.984 | I23: 250 | J23: =SUM(G23:I23) -> 1294.184 | K23: 211.2 | L23: 20.28 | M23: 70 | N23: =SUM(K23:M23) -> 301.48 | O23: 1217.2 | P23: 10.816 | Q23: 650 | R23: =SUM(O23:Q23) -> 1878.016 | S23: 120 | T23: 13.52 | U23: 70 | V23: =SUM(S23:U23) -> 203.52 | W23: 0 | X23: 270.4 | Y23: 20 | Z23: =SUM(W23:Y23) -> 290.4 | AA23: =(F23+J23+N23+R23+V23+Z23) -> 4212.256 | AB23: kg/hari | AD23: 16 | AE23: 16 | AF23: =(C23+G23+K23+O23+S23+W23) -> 2746.4 | AG23: =(D23+H23+L23+P23+T23+X23) -> 375.856 | AH23: =(E23+I23+M23+Q23++U23+Y23) -> 1090 | AJ23: 16 | AK23: 16 | AL23: =AF23 -> 2746.4 | AM23: =AL23/AA23 -> 0.65200216 | AN23: =AG23 -> 375.856 | AO23: =AN23/AA23 -> 0.089229145 | AP23: =AH23 -> 1090 | AQ23: =AP23/AA23 -> 0.2587687
A24: 17 | B24: 17 | C24: 175.2 | D24: 16.224 | E24: 45 | F24: =SUM(C24:E24) -> 236.424 | G24: 813.6 | H24: 9.464 | I24: 230 | J24: =SUM(G24:I24) -> 1053.064 | K24: 209.6 | L24: 28.392 | M24: 100 | N24: =SUM(K24:M24) -> 337.992 | O24: 1214 | P24: =(((((0.6+1)*1.3)*1.3)*2)*2)*2 -> 21.632 | Q24: 520 | R24: =SUM(O24:Q24) -> 1755.632 | S24: 80 | T24: 27.04 | U24: 60 | V24: =SUM(S24:U24) -> 167.04 | W24: 0 | X24: =(((((20+1)*1.3)*1.3)*2)*2)*2 -> 283.92 | Y24: 35 | Z24: =SUM(W24:Y24) -> 318.92 | AA24: =(F24+J24+N24+R24+V24+Z24) -> 3869.072 | AB24: kg/hari | AD24: 17 | AE24: 17 | AF24: =(C24+G24+K24+O24+S24+W24) -> 2492.4 | AG24: =(D24+H24+L24+P24+T24+X24) -> 386.672 | AH24: =(E24+I24+M24+Q24++U24+Y24) -> 990 | AJ24: 17 | AK24: 17 | AL24: =AF24 -> 2492.4 | AM24: =AL24/AA24 -> 0.64418548 | AN24: =AG24 -> 386.672 | AO24: =AN24/AA24 -> 0.09993921 | AP24: =AH24 -> 990 | AQ24: =AP24/AA24 -> 0.25587531
A25: 18 | B25: 18 | C25: 214.8 | D25: =(((((0.9+1)*1.3)*1.3)*2)*2)*2 -> 25.688 | E25: 65 | F25: =SUM(C25:E25) -> 305.488 | G25: 1216.8 | H25: =(((((3.3+1)*1.3)*1.3)*2)*2)*2 -> 58.136 | I25: 550 | J25: =SUM(G25:I25) -> 1824.936 | K25: 330 | L25: 20.28 | M25: 120 | N25: =SUM(K25:M25) -> 470.28 | O25: 1214.4 | P25: 37.856 | Q25: 1200 | R25: =SUM(O25:Q25) -> 2452.256 | S25: 120 | T25: 27.04 | U25: 135 | V25: =SUM(S25:U25) -> 282.04 | W25: 80 | X25: 0 | Y25: 120 | Z25: =SUM(W25:Y25) -> 200 | AA25: =(F25+J25+N25+R25+V25+Z25) -> 5535 | AB25: kg/hari | AD25: 18 | AE25: 18 | AF25: =(C25+G25+K25+O25+S25+W25) -> 3176 | AG25: =(D25+H25+L25+P25+T25+X25) -> 169 | AH25: =(E25+I25+M25+Q25++U25+Y25) -> 2190 | AJ25: 18 | AK25: 18 | AL25: =AF25 -> 3176 | AM25: =AL25/AA25 -> 0.57380307 | AN25: =AG25 -> 169 | AO25: =AN25/AA25 -> 0.030532972 | AP25: =AH25 -> 2190 | AQ25: =AP25/AA25 -> 0.39566396
A26: 19 | B26: 19 | C26: 179.2 | D26: =(((((3.4+1)*1.3)*1.3)*2)*2)*2 -> 59.488 | E26: 30 | F26: =SUM(C26:E26) -> 268.688 | G26: 815.2 | H26: 16.224 | I26: 200 | J26: =SUM(G26:I26) -> 1031.424 | K26: 411.2 | L26: 62.192 | M26: 100 | N26: =SUM(K26:M26) -> 573.392 | O26: 1216.8 | P26: =(((((2.3+1)*1.3)*1.3)*2)*2)*2 -> 44.616 | Q26: 1090 | R26: =SUM(O26:Q26) -> 2351.416 | S26: 80 | T26: 27.04 | U26: 60 | V26: =SUM(S26:U26) -> 167.04 | W26: 0 | X26: 0 | Y26: 20 | Z26: =SUM(W26:Y26) -> 20 | AA26: =(F26+J26+N26+R26+V26+Z26) -> 4411.96 | AB26: kg/hari | AD26: 19 | AE26: 19 | AF26: =(C26+G26+K26+O26+S26+W26) -> 2702.4 | AG26: =(D26+H26+L26+P26+T26+X26) -> 209.56 | AH26: =(E26+I26+M26+Q26++U26+Y26) -> 1500 | AJ26: 19 | AK26: 19 | AL26: =AF26 -> 2702.4 | AM26: =AL26/AA26 -> 0.61251689 | AN26: =AG26 -> 209.56 | AO26: =AN26/AA26 -> 0.047498164 | AP26: =AH26 -> 1500 | AQ26: =AP26/AA26 -> 0.33998495
A27: 20 | B27: 20 | C27: 80 | D27: 0 | E27: 15 | F27: =SUM(C27:E27) -> 95 | G27: 400 | H27: 27.04 | I27: 80 | J27: =SUM(G27:I27) -> 507.04 | K27: 0 | L27: 0 | N27: =SUM(K27:M27) -> 0 | O27: 800 | P27: 0 | Q27: 550 | R27: =SUM(O27:Q27) -> 1350 | S27: 40 | T27: 0 | U27: 25 | V27: =SUM(S27:U27) -> 65 | W27: 0 | X27: 13.52 | Y27: 30 | Z27: =SUM(W27:Y27) -> 43.52 | AA27: =(F27+J27+N27+R27+V27+Z27) -> 2060.56 | AB27: kg/hari | AD27: 20 | AE27: 20 | AF27: =(C27+G27+K27+O27+S27+W27) -> 1320 | AG27: =(D27+H27+L27+P27+T27+X27) -> 40.56 | AH27: =(E27+I27+M27+Q27++U27+Y27) -> 700 | AJ27: 20 | AK27: 20 | AL27: =AF27 -> 1320 | AM27: =AL27/AA27 -> 0.64060255 | AN27: =AG27 -> 40.56 | AO27: =AN27/AA27 -> 0.019683969 | AP27: =AH27 -> 700 | AQ27: =AP27/AA27 -> 0.33971348
A28: 21 | B28: 21 | C28: 0 | D28: 0 | E28: 0 | F28: =SUM(C28:E28) -> 0 | G28: 0 | H28: 0 | I28: 0 | J28: =SUM(G28:I28) -> 0 | K28: 0 | L28: 0 | N28: =SUM(K28:M28) -> 0 | O28: 0 | P28: 0 | Q28: 0 | R28: =SUM(O28:Q28) -> 0 | S28: 0 | T28: 0 | V28: =SUM(S28:U28) -> 0 | W28: 0 | X28: 0 | Y28: 0 | Z28: =SUM(W28:Y28) -> 0 | AA28: =(F28+J28+N28+R28+V28+Z28) -> 0 | AB28: kg/hari | AD28: 21 | AE28: 21 | AF28: =(C28+G28+K28+O28+S28+W28) -> 0 | AG28: =(D28+H28+L28+P28+T28+X28) -> 0 | AH28: =(E28+I28+M28+Q28++U28+Y28) -> 0 | AJ28: 21 | AK28: 21 | AL28: =AF28 -> 0 | AM28: =AL28/AA28 -> #DIV/0! | AN28: =AG28 -> 0 | AO28: =AN28/AA28 -> #DIV/0! | AP28: =AH28 -> 0 | AQ28: =AP28/AA28 -> #DIV/0!
A29: 22 | B29: 22 | C29: 142.8 | D29: =(((((1.2+1)*1.3)*1.3)*2)*2)*2 -> 29.744 | E29: 70 | F29: =SUM(C29:E29) -> 242.544 | G29: 813.2 | H29: =(((((0.8+1)*1.3)*1.3)*2)*2)*2 -> 24.336 | I29: 200 | J29: =SUM(G29:I29) -> 1037.536 | K29: 411.6 | L29: 56.784 | M29: 120 | N29: =SUM(K29:M29) -> 588.384 | O29: 1221.2 | P29: 67.6 | Q29: 510 | R29: =SUM(O29:Q29) -> 1798.8 | S29: 160 | T29: 40.56 | U29: 70 | V29: =SUM(S29:U29) -> 270.56 | W29: 0 | X29: 270.4 | Y29: 23 | Z29: =SUM(W29:Y29) -> 293.4 | AA29: =(F29+J29+N29+R29+V29+Z29) -> 4231.224 | AB29: kg/hari | AD29: 22 | AE29: 22 | AF29: =(C29+G29+K29+O29+S29+W29) -> 2748.8 | AG29: =(D29+H29+L29+P29+T29+X29) -> 489.424 | AH29: =(E29+I29+M29+Q29++U29+Y29) -> 993 | AJ29: 22 | AK29: 22 | AL29: =AF29 -> 2748.8 | AM29: =AL29/AA29 -> 0.64964653 | AN29: =AG29 -> 489.424 | AO29: =AN29/AA29 -> 0.1156696 | AP29: =AH29 -> 993 | AQ29: =AP29/AA29 -> 0.23468386
A30: 23 | B30: 23 | C30: 134.8 | D30: 154.128 | E30: 55 | F30: =SUM(C30:E30) -> 343.928 | G30: 817.6 | H30: 13.52 | I30: 240 | J30: =SUM(G30:I30) -> 1071.12 | K30: 212.8 | L30: 20.28 | M30: 150 | N30: =SUM(K30:M30) -> 383.08 | O30: 815.6 | P30: =(((((1.2+1)*1.3)*1.3)*2)*2)*2 -> 29.744 | Q30: 400 | R30: =SUM(O30:Q30) -> 1245.344 | S30: 60 | T30: 40.56 | U30: 80 | V30: =SUM(S30:U30) -> 180.56 | W30: 0 | X30: 270.4 | Y30: 20 | Z30: =SUM(W30:Y30) -> 290.4 | AA30: =(F30+J30+N30+R30+V30+Z30) -> 3514.432 | AB30: kg/hari | AD30: 23 | AE30: 23 | AF30: =(C30+G30+K30+O30+S30+W30) -> 2040.8 | AG30: =(D30+H30+L30+P30+T30+X30) -> 528.632 | AH30: =(E30+I30+M30+Q30++U30+Y30) -> 945 | AJ30: 23 | AK30: 23 | AL30: =AF30 -> 2040.8 | AM30: =AL30/AA30 -> 0.58069128 | AN30: =AG30 -> 528.632 | AO30: =AN30/AA30 -> 0.15041748 | AP30: =AH30 -> 945 | AQ30: =AP30/AA30 -> 0.26889125
A31: 24 | B31: 24 | C31: 93.6 | D31: 10.816 | E31: 20 | F31: =SUM(C31:E31) -> 124.416 | G31: 420.4 | H31: 13.52 | I31: 100 | J31: =SUM(G31:I31) -> 533.92 | K31: 54 | L31: 12.168 | M31: 150 | N31: =SUM(K31:M31) -> 216.168 | O31: 815.6 | P31: 17.576 | Q31: 250 | R31: =SUM(O31:Q31) -> 1083.176 | S31: 40 | T31: 40.56 | U31: 40 | V31: =SUM(S31:U31) -> 120.56 | W31: 100 | X31: =(((((20+1)*1.3)*1.3)*2)*2)*2 -> 283.92 | Y31: 80 | Z31: =SUM(W31:Y31) -> 463.92 | AA31: =(F31+J31+N31+R31+V31+Z31) -> 2542.16 | AB31: kg/hari | AD31: 24 | AE31: 24 | AF31: =(C31+G31+K31+O31+S31+W31) -> 1523.6 | AG31: =(D31+H31+L31+P31+T31+X31) -> 378.56 | AH31: =(E31+I31+M31+Q31++U31+Y31) -> 640 | AJ31: 24 | AK31: 24 | AL31: =AF31 -> 1523.6 | AM31: =AL31/AA31 -> 0.59933285 | AN31: =AG31 -> 378.56 | AO31: =AN31/AA31 -> 0.14891274 | AP31: =AH31 -> 640 | AQ31: =AP31/AA31 -> 0.25175441
A32: 25 | B32: 25 | C32: 136.8 | D32: =(((((1.4+1)*1.3)*1.3)*2)*2)*2 -> 32.448 | E32: 30 | F32: =SUM(C32:E32) -> 199.248 | G32: 215.6 | H32: =(((((2.3+1)*1.3)*1.3)*2)*2)*2 -> 44.616 | I32: 82 | J32: =SUM(G32:I32) -> 342.216 | K32: 291.2 | L32: 10.816 | M32: 80 | N32: =SUM(K32:M32) -> 382.016 | O32: 820 | P32: =(((((1.9+1)*1.3)*1.3)*2)*2)*2 -> 39.208 | Q32: 360 | R32: =SUM(O32:Q32) -> 1219.208 | S32: 80 | T32: 13.52 | U32: 40 | V32: =SUM(S32:U32) -> 133.52 | W32: 0 | X32: 0 | Y32: 47 | Z32: =SUM(W32:Y32) -> 47 | AA32: =(F32+J32+N32+R32+V32+Z32) -> 2323.208 | AB32: kg/hari | AD32: 25 | AE32: 25 | AF32: =(C32+G32+K32+O32+S32+W32) -> 1543.6 | AG32: =(D32+H32+L32+P32+T32+X32) -> 140.608 | AH32: =(E32+I32+M32+Q32++U32+Y32) -> 639 | AJ32: 25 | AK32: 25 | AL32: =AF32 -> 1543.6 | AM32: =AL32/AA32 -> 0.66442609 | AN32: =AG32 -> 140.608 | AO32: =AN32/AA32 -> 0.060523208 | AP32: =AH32 -> 639 | AQ32: =AP32/AA32 -> 0.27505071
A33: 26 | B33: 26 | C33: 215.2 | D33: 8.112 | E33: 50 | F33: =SUM(C33:E33) -> 273.312 | G33: 814 | H33: 25.688 | I33: 250 | J33: =SUM(G33:I33) -> 1089.688 | K33: 172 | L33: 32.448 | M33: 69 | N33: =SUM(K33:M33) -> 273.448 | O33: 817.2 | P33: 14.872 | Q33: 450 | R33: =SUM(O33:Q33) -> 1282.072 | S33: 120 | T33: 40.56 | U33: 50 | V33: =SUM(S33:U33) -> 210.56 | W33: 0 | X33: 13.52 | Y33: 25 | Z33: =SUM(W33:Y33) -> 38.52 | AA33: =(F33+J33+N33+R33+V33+Z33) -> 3167.6 | AB33: kg/hari | AD33: 26 | AE33: 26 | AF33: =(C33+G33+K33+O33+S33+W33) -> 2138.4 | AG33: =(D33+H33+L33+P33+T33+X33) -> 135.2 | AH33: =(E33+I33+M33+Q33++U33+Y33) -> 894 | AJ33: 26 | AK33: 26 | AL33: =AF33 -> 2138.4 | AM33: =AL33/AA33 -> 0.67508524 | AN33: =AG33 -> 135.2 | AO33: =AN33/AA33 -> 0.042682157 | AP33: =AH33 -> 894 | AQ33: =AP33/AA33 -> 0.28223261
A34: 27 | B34: 27 | C34: 40 | D34: 67.6 | E34: 10 | F34: =SUM(C34:E34) -> 117.6 | G34: 160 | H34: 13.52 | I34: 30 | J34: =SUM(G34:I34) -> 203.52 | K34: 0 | L34: 0 | N34: =SUM(K34:M34) -> 0 | O34: 200 | P34: 13.52 | Q34: 150 | R34: =SUM(O34:Q34) -> 363.52 | S34: 20 | T34: 0 | U34: 20 | V34: =SUM(S34:U34) -> 40 | W34: 0 | X34: 0 | Y34: 21 | Z34: =SUM(W34:Y34) -> 21 | AA34: =(F34+J34+N34+R34+V34+Z34) -> 745.64 | AB34: kg/hari | AD34: 27 | AE34: 27 | AF34: =(C34+G34+K34+O34+S34+W34) -> 420 | AG34: =(D34+H34+L34+P34+T34+X34) -> 94.64 | AH34: =(E34+I34+M34+Q34++U34+Y34) -> 231 | AJ34: 27 | AK34: 27 | AL34: =AF34 -> 420 | AM34: =AL34/AA34 -> 0.5632745 | AN34: =AG34 -> 94.64 | AO34: =AN34/AA34 -> 0.12692452 | AP34: =AH34 -> 231 | AQ34: =AP34/AA34 -> 0.30980098
A35: 28 | B35: 28 | C35: 0 | D35: 27.04 | E35: =[1]Juli!O33+[2]Juli!O33+[3]Juli!O33 -> 0 | F35: =SUM(C35:E35) -> 27.04 | G35: 0 | H35: 0 | I35: 0 | J35: =SUM(G35:I35) -> 0 | K35: 0 | L35: 0 | N35: =SUM(K35:M35) -> 0 | O35: 0 | P35: 0 | Q35: 0 | R35: =SUM(O35:Q35) -> 0 | S35: 0 | T35: 0 | V35: =SUM(S35:U35) -> 0 | W35: 0 | X35: 0 | Y35: 0 | Z35: =SUM(W35:Y35) -> 0 | AA35: =(F35+J35+N35+R35+V35+Z35) -> 27.04 | AB35: kg/hari | AD35: 28 | AE35: 28 | AF35: =(C35+G35+K35+O35+S35+W35) -> 0 | AG35: =(D35+H35+L35+P35+T35+X35) -> 27.04 | AH35: =(E35+I35+M35+Q35++U35+Y35) -> 0 | AJ35: 28 | AK35: 28 | AL35: =AF35 -> 0 | AM35: =AL35/AA35 -> 0 | AN35: =AG35 -> 27.04 | AO35: =AN35/AA35 -> 1 | AP35: =AH35 -> 0 | AQ35: =AP35/AA35 -> 0
A36: 29 | B36: 29 | C36: 179.6 | D36: 9.464 | E36: 50 | F36: =SUM(C36:E36) -> 239.064 | G36: 1018.4 | H36: =(((((0.8+1)*1.3)*1.3)*2)*2)*2 -> 24.336 | I36: 300 | J36: =SUM(G36:I36) -> 1342.736 | K36: 251.6 | L36: 18.928 | M36: 60 | N36: =SUM(K36:M36) -> 330.528 | O36: 1216.4 | P36: 35.152 | Q36: 1000 | R36: =SUM(O36:Q36) -> 2251.552 | S36: 160 | T36: 40.56 | U36: 60 | V36: =SUM(S36:U36) -> 260.56 | W36: 20 | X36: =(((((20+1)*1.3)*1.3)*2)*2)*2 -> 283.92 | Y36: 20 | Z36: =SUM(W36:Y36) -> 323.92 | AA36: =(F36+J36+N36+R36+V36+Z36) -> 4748.36 | AB36: kg/hari | AD36: 29 | AE36: 29 | AF36: =(C36+G36+K36+O36+S36+W36) -> 2846 | AG36: =(D36+H36+L36+P36+T36+X36) -> 412.36 | AH36: =(E36+I36+M36+Q36++U36+Y36) -> 1490 | AJ36: 29 | AK36: 29 | AL36: =AF36 -> 2846 | AM36: =AL36/AA36 -> 0.59936483 | AN36: =AG36 -> 412.36 | AO36: =AN36/AA36 -> 0.086842615 | AP36: =AH36 -> 1490 | AQ36: =AP36/AA36 -> 0.31379255
A37: 30 | B37: 30 | C37: 134.8 | D37: 27.04 | E37: 40 | F37: =SUM(C37:E37) -> 201.84 | G37: 821.2 | H37: 10.816 | I37: 290 | J37: =SUM(G37:I37) -> 1122.016 | K37: 415.2 | L37: 16.224 | M37: 100 | N37: =SUM(K37:M37) -> 531.424 | O37: 1212 | P37: =(((((0.8+1)*1.3)*1.3)*2)*2)*2 -> 24.336 | Q37: 500 | R37: =SUM(O37:Q37) -> 1736.336 | S37: 40 | T37: 27.04 | U37: 50 | V37: =SUM(S37:U37) -> 117.04 | W37: 20 | X37: 270.4 | Y37: 20 | Z37: =SUM(W37:Y37) -> 310.4 | AA37: =(F37+J37+N37+R37+V37+Z37) -> 4019.056 | AB37: kg/hari | AD37: 30 | AE37: 30 | AF37: =(C37+G37+K37+O37+S37+W37) -> 2643.2 | AG37: =(D37+H37+L37+P37+T37+X37) -> 375.856 | AH37: =(E37+I37+M37+Q37++U37+Y37) -> 1000 | AJ37: 30 | AK37: 30 | AL37: =AF37 -> 2643.2 | AM37: =AL37/AA37 -> 0.65766688 | AN37: =AG37 -> 375.856 | AO37: =AN37/AA37 -> 0.093518478 | AP37: =AH37 -> 1000 | AQ37: =AP37/AA37 -> 0.24881465
A38: 31 | B38: 31 | C38: 135.2 | D38: =(((((1.2+1)*1.3)*1.3)*2)*2)*2 -> 29.744 | E38: 50 | F38: =SUM(C38:E38) -> 214.944 | G38: 1219.6 | H38: 8.112 | I38: 360 | J38: =SUM(G38:I38) -> 1587.712 | K38: 16.8 | L38: 10.816 | N38: =SUM(K38:M38) -> 27.616 | O38: 338.8 | P38: 22.984 | Q38: 1000 | R38: =SUM(O38:Q38) -> 1361.784 | S38: 80 | T38: 54.08 | U38: 80 | V38: =SUM(S38:U38) -> 214.08 | W38: 0 | X38: 270.4 | Y38: 20 | Z38: =SUM(W38:Y38) -> 290.4 | AA38: =(F38+J38+N38+R38+V38+Z38) -> 3696.536 | AB38: kg/hari | AD38: 31 | AE38: 31 | AF38: =(C38+G38+K38+O38+S38+W38) -> 1790.4 | AG38: =(D38+H38+L38+P38+T38+X38) -> 396.136 | AH38: =(E38+I38+M38+Q38++U38+Y38) -> 1510 | AJ38: 31 | AK38: 31 | AL38: =AF38 -> 1790.4 | AM38: =AL38/AA38 -> 0.48434534 | AN38: =AG38 -> 396.136 | AO38: =AN38/AA38 -> 0.10716411 | AP38: =AH38 -> 1510 | AQ38: =AP38/AA38 -> 0.40849054
A39: Total/jenis (kg/bulan) | C39: =SUM(C8:C38) -> 4518 | D39: =SUM(D8:D38) -> 1032.928 | E39: =SUM(E8:E38) -> 1395 | F39: =SUM(F8:F38) -> 6945.928 | G39: =SUM(G8:G38) -> 20472 | H39: =SUM(H8:H38) -> 980.2 | I39: =SUM(I8:I38) -> 6012 | J39: =SUM(J8:J38) -> 27464.2 | ... AA39: =SUM(AA8:AA38) -> 96789.368 | AB39: kg/bulan | AD39: Total Jenis Sampah Terpilah (kg/bulan) | AF39: =SUM(AF8:AF38) -> 59464.4 | AG39: =SUM(AG8:AG38) -> 10354.968 | AH39: =SUM(AH8:AH38) -> 26970 | AJ39: Total Pengelolaan Sampah(kg/bulan) | AL39: =SUM(AL8:AL38) -> 59464.4 | AM39: - | AN39: =SUM(AN8:AN38) -> 10354.968 | AO39: - | AP39: =SUM(AP8:AP38) -> 26970 | AQ39: -
A40: Total/jenis (ton/bulan) | C40: =C39/1000 -> 4.518 | D40: =D39/1000 -> 1.032928 | E40: =E39/1000 -> 1.395 | F40: =F39/1000 -> 6.945928 | G40: =G39/1000 -> 20.472 | H40: =H39/1000 -> 0.9802 | I40: =I39/1000 -> 6.012 | J40: =J39/1000 -> 27.4642 | ... AA40: =AA39/1000 -> 96.789368 | AB40: ton/bulan | AD40: Total Jenis Sampah Terpilah (ton/bulan) | AF40: =AF39/1000 -> 59.4644 | AG40: =AG39/1000 -> 10.354968 | AH40: =AH39/1000 -> 26.97 | AJ40: Total Sampah terkelola (ton/bulan) | AL40: =AL39/1000 -> 59.4644 | AM40: =AL40/AA40 -> 0.61436913 | AN40: =AN39/1000 -> 10.354968 | AO40: =AN40/AA40 -> 0.10698456 | AP40: =AP39/1000 -> 26.97 | AQ40: =AP40/AA40 -> 0.27864631
...

Sheet Agustus
A1: Perusahaan : | B1: ='Rekap Neraca Pengelolaan Sampah'!C3 -> PT PELINDO DAYA SEJAHTERA
A2: Tahun | B2: ='Rekap Neraca Pengelolaan Sampah'!D2 -> 2024
A3: Bulan: | B3: Agustus | C3: REKAMAN TIMBULAN SAMPAH | G3: REKAMAN TIMBULAN SAMPAH | K3: REKAMAN TIMBULAN SAMPAH | O3: REKAMAN TIMBULAN SAMPAH | S3: REKAMAN TIMBULAN SAMPAH | W3: REKAMAN TIMBULAN SAMPAH | AA3: TOTAL TIMBULAN SAMPAH DI SELURUH AREA | AB3: Satuan | AD3: REKAMAN REKAP JUMLAH SAMPAH BERDASARKAN | AJ3: REKAMAN REKAP JUMLAH PENGELOLAAN SAMPAH
A4: No | B4: Tanggal | C4: (kg/hari) | G4: (kg/hari) | K4: (kg/hari) | O4: (kg/hari) | S4: (kg/hari) | W4: (kg/hari) | AD4: JENIS SAMPAH TERPILAH | AJ4: DI SELURUH AREA
C5: Sumber sampah | G5: Sumber sampah | K5: Sumber sampah | O5: Sumber sampah | S5: Sumber sampah | W5: Sumber sampah | AD5: (kg/hari) | AJ5: Bulan : | AK5: =B3 -> Agustus | AL5: Tahun : | AM5: =B4 -> Tanggal
C6: Area Kantor | G6: Area Tempat Parkir/Taman/Jalan | K6: Area Ruang Tunggu | O6: Area Tempat Makan | S6: Sampah Kapal (Khusus Pelabuhan) | W6: Area Lain (sebutkan jika ada) | AD6: Bulan : | AE6: =B3 -> Agustus | AF6: Tahun : | AG6: =B4 -> Tanggal | AJ6: Sampah Terkelola (kg/hari)
C7: Sampah Organik Terpilah | D7: Sampah Anorganik Terpilah | E7: Sampah Lainnya dan/atau Residu | F7: Total Timbulan Sampah | G7: Sampah Organik Terpilah | H7: Sampah Anorganik Terpilah | I7: Sampah Lainnya dan/atau Residu | J7: Total Timbulan Sampah | K7: Sampah Organik Terpilah | L7: Sampah Anorganik Terpilah | M7: Sampah Lainnya dan/atau Residu | N7: Total Timbulan Sampah | O7: Sampah Organik Terpilah | P7: Sampah Anorganik Terpilah | Q7: Sampah Lainnya dan/atau Residu | R7: Total Timbulan Sampah | S7: Sampah Organik Terpilah | T7: Sampah Anorganik Terpilah | U7: Sampah Lainnya dan/atau Residu | V7: Total Timbulan Sampah | W7: Sampah Organik Terpilah | X7: Sampah Anorganik Terpilah | Y7: Sampah Lainnya dan/atau Residu | Z7: Total Timbulan Sampah | AD7: No. | AE7: Tanggal | AF7: Jumlah Sampah Organik | AG7: Jumlah Sampah Anorganik | AH7: Jumlah Sampah Residu ke TPA | AJ7: No. | AK7: Tanggal | AL7: Kompos / Pakan Ternak | AM7: Prosentase Kompos/pakan ternak | AN7: Bank Sampah / TPS3R / PDU | AO7: Prosentase Bank Sampah / TPS3R / PDU | AP7: Sampah Residu yang diangkut ke TPA | AQ7: Prosentase Sampah Residu yang diangkut ke TPA
A8: 1 | B8: 01 | C8: 1214 | D8: =((((1+1)*1.3)*1.3)*2)*2 -> 13.52 | E8: 130 | F8: =SUM(C8:E8) -> 1357.52 | G8: 810 | H8: =((((8.8+1)*1.3)*1.3)*2)*2 -> 66.248 | I8: 500 | J8: =SUM(G8:I8) -> 1376.248 | K8: 22.8 | L8: 10.14 | N8: =SUM(K8:M8) -> 32.94 | O8: 1220.4 | P8: =((((46+1)*1.3)*1.3)*2)*2 -> 317.72 | Q8: 900 | R8: =SUM(O8:Q8) -> 2438.12 | S8: 320 | T8: =((((3+3)*1.3)*1.3)*2)*2 -> 40.56 | U8: 180 | V8: =SUM(S8:U8) -> 540.56 | W8: 100 | X8: 20.28 | Y8: 75 | Z8: =SUM(W8:Y8) -> 195.28 | AA8: =(F8+J8+N8+R8+V8+Z8) -> 5940.668 | AB8: kg/hari | AD8: 1 | AE8: 01 | AF8: =(C8+G8+K8+O8+S8+W8) -> 3687.2 | AG8: =(D8+H8+L8+P8+T8+X8) -> 468.468 | AH8: =(E8+I8+M8+Q8++U8+Y8) -> 1785 | AJ8: 1 | AK8: 01 | AL8: =AF8 -> 3687.2 | AM8: =AL8/AA8 -> 0.62067094 | AN8: =AG8 -> 468.468 | AO8: =AN8/AA8 -> 0.078857798 | AP8: =AH8 -> 1785 | AQ8: =AP8/AA8 -> 0.30047126
A9: 2 | B9: 02 | C9: 211.6 | D9: =((((1+1)*1.3)*1.3)*2)*2 -> 13.52 | E9: 105 | F9: =SUM(C9:E9) -> 330.12 | G9: 1018 | H9: 31.096 | I9: 450 | J9: =SUM(G9:I9) -> 1499.096 | K9: 19.2 | L9: 9.464 | N9: =SUM(K9:M9) -> 28.664 | O9: 819.2 | P9: 302.172 | Q9: 600 | R9: =SUM(O9:Q9) -> 1721.372 | S9: 120 | T9: =((((2+2)*1.3)*1.3)*2)*2 -> 27.04 | U9: 100 | V9: =SUM(S9:U9) -> 247.04 | W9: 0 | X9: 20.28 | Z9: =SUM(W9:Y9) -> 20.28 | AA9: =(F9+J9+N9+R9+V9+Z9) -> 3846.572 | AB9: kg/hari | AD9: 2 | AE9: 02 | AF9: =(C9+G9+K9+O9+S9+W9) -> 2188 | AG9: =(D9+H9+L9+P9+T9+X9) -> 403.572 | AH9: =(E9+I9+M9+Q9++U9+Y9) -> 1255 | AJ9: 2 | AK9: 02 | AL9: =AF9 -> 2188 | AM9: =AL9/AA9 -> 0.56881816 | AN9: =AG9 -> 403.572 | AO9: =AN9/AA9 -> 0.10491731 | AP9: =AH9 -> 1255 | AQ9: =AP9/AA9 -> 0.32626453
A10: 3 | B10: 03 | C10: 160 | D10: 0 | E10: 100 | F10: =SUM(C10:E10) -> 260 | G10: 200 | H10: 6.76 | I10: 150 | J10: =SUM(G10:I10) -> 356.76 | K10: 0 | L10: 0 | N10: =SUM(K10:M10) -> 0 | O10: 0 | P10: 0 | Q10: 0 | R10: =SUM(O10:Q10) -> 0 | S10: 0 | T10: 0 | V10: =SUM(S10:U10) -> 0 | W10: 0 | X10: 6.76 | Z10: =SUM(W10:Y10) -> 6.76 | AA10: =(F10+J10+N10+R10+V10+Z10) -> 623.52 | AB10: kg/hari | AD10: 3 | AE10: 03 | AF10: =(C10+G10+K10+O10+S10+W10) -> 360 | AG10: =(D10+H10+L10+P10+T10+X10) -> 13.52 | AH10: =(E10+I10+M10+Q10++U10+Y10) -> 250 | AJ10: 3 | AK10: 03 | AL10: =AF10 -> 360 | AM10: =AL10/AA10 -> 0.57736721 | AN10: =AG10 -> 13.52 | AO10: =AN10/AA10 -> 0.021683346 | AP10: =AH10 -> 250 | AQ10: =AP10/AA10 -> 0.40094945
A11: 4 | B11: 04 | C11: 0 | D11: 6.76 | E11: =[2]Agustus!O9+[1]Agustus!O9+[3]Agustus!O9 -> 0 | F11: =SUM(C11:E11) -> 6.76 | G11: 0 | H11: 0 | I11: 0 | J11: =SUM(G11:I11) -> 0 | K11: 0 | L11: 0 | N11: =SUM(K11:M11) -> 0 | O11: 0 | P11: 0 | Q11: 0 | R11: =SUM(O11:Q11) -> 0 | S11: 0 | T11: 0 | V11: =SUM(S11:U11) -> 0 | W11: 0 | X11: 0 | Z11: =SUM(W11:Y11) -> 0 | AA11: =(F11+J11+N11+R11+V11+Z11) -> 6.76 | AB11: kg/hari | AD11: 4 | AE11: 04 | AF11: =(C11+G11+K11+O11+S11+W11) -> 0 | AG11: =(D11+H11+L11+P11+T11+X11) -> 6.76 | AH11: =(E11+I11+M11+Q11++U11+Y11) -> 0 | AJ11: 4 | AK11: 04 | AL11: =AF11 -> 0 | AM11: =AL11/AA11 -> 0 | AN11: =AG11 -> 6.76 | AO11: =AN11/AA11 -> 1 | AP11: =AH11 -> 0 | AQ11: =AP11/AA11 -> 0
A12: 5 | B12: 05 | C12: 134.8 | D12: 16.9 | E12: 40 | F12: =SUM(C12:E12) -> 191.7 | G12: 214 | H12: =((((6.2+1)*1.3)*1.3)*2)*2 -> 48.672 | I12: 150 | J12: =SUM(G12:I12) -> 412.672 | K12: 15.6 | L12: 12.844 | N12: =SUM(K12:M12) -> 28.444 | O12: 815.6 | P12: =((((43.5+1)*1.3)*1.3)*2)*2 -> 300.82 | Q12: 300 | R12: =SUM(O12:Q12) -> 1416.42 | S12: 80 | T12: =((((2+3)*1.3)*1.3)*2)*2 -> 33.8 | U12: 90 | V12: =SUM(S12:U12) -> 203.8 | W12: 0 | X12: 13.52 | Y12: 5 | Z12: =SUM(W12:Y12) -> 18.52 | AA12: =(F12+J12+N12+R12+V12+Z12) -> 2271.556 | AB12: kg/hari | AD12: 5 | AE12: 05 | AF12: =(C12+G12+K12+O12+S12+W12) -> 1260 | AG12: =(D12+H12+L12+P12+T12+X12) -> 426.556 | AH12: =(E12+I12+M12+Q12++U12+Y12) -> 585 | AJ12: 5 | AK12: 05 | AL12: =AF12 -> 1260 | AM12: =AL12/AA12 -> 0.55468586 | AN12: =AG12 -> 426.556 | AO12: =AN12/AA12 -> 0.18778142 | AP12: =AH12 -> 585 | AQ12: =AP12/AA12 -> 0.25753272
A13: 6 | B13: 06 | C13: 89.2 | D13: =((((2.2+1)*1.3)*1.3)*2)*2 -> 21.632 | E13: 30 | F13: =SUM(C13:E13) -> 140.832 | G13: 418 | H13: 33.8 | I13: 250 | J13: =SUM(G13:I13) -> 701.8 | K13: 216.4 | L13: 13.52 | M13: 170 | N13: =SUM(K13:M13) -> 399.92 | O13: 816.8 | P13: 305.552 | Q13: 500 | R13: =SUM(O13:Q13) -> 1622.352 | S13: 120 | T13: =((((2+3)*1.3)*1.3)*2)*2 -> 33.8 | U13: 70 | V13: =SUM(S13:U13) -> 223.8 | W13: 0 | X13: 13.52 | Y13: 5 | Z13: =SUM(W13:Y13) -> 18.52 | AA13: =(F13+J13+N13+R13+V13+Z13) -> 3107.224 | AB13: kg/hari | AD13: 6 | AE13: 06 | AF13: =(C13+G13+K13+O13+S13+W13) -> 1660.4 | AG13: =(D13+H13+L13+P13+T13+X13) -> 421.824 | AH13: =(E13+I13+M13+Q13++U13+Y13) -> 1025 | AJ13: 6 | AK13: 06 | AL13: =AF13 -> 1660.4 | AM13: =AL13/AA13 -> 0.53436765 | AN13: =AG13 -> 421.824 | AO13: =AN13/AA13 -> 0.1357559 | AP13: =AH13 -> 1025 | AQ13: =AP13/AA13 -> 0.32987644
A14: 7 | B14: 07 | C14: 211.2 | D14: =((((4.4+1)*1.3)*1.3)*2)*2 -> 36.504 | E14: 140 | F14: =SUM(C14:E14) -> 387.704 | G14: 414 | H14: =((((4.4+1)*1.3)*1.3)*2)*2 -> 36.504 | I14: 250 | J14: =SUM(G14:I14) -> 700.504 | K14: 418 | L14: 33.8 | M14: 110 | N14: =SUM(K14:M14) -> 561.8 | O14: 621.6 | P14: =((((44.6+1)*1.3)*1.3)*2)*2 -> 308.256 | Q14: 500 | R14: =SUM(O14:Q14) -> 1429.856 | S14: 200 | T14: =((((2+4)*1.3)*1.3)*2)*2 -> 40.56 | U14: 80 | V14: =SUM(S14:U14) -> 320.56 | W14: 200 | X14: 13.52 | Y14: 155 | Z14: =SUM(W14:Y14) -> 368.52 | AA14: =(F14+J14+N14+R14+V14+Z14) -> 3768.944 | AB14: kg/hari | AD14: 7 | AE14: 07 | AF14: =(C14+G14+K14+O14+S14+W14) -> 2064.8 | AG14: =(D14+H14+L14+P14+T14+X14) -> 469.144 | AH14: =(E14+I14+M14+Q14++U14+Y14) -> 1235 | AJ14: 7 | AK14: 07 | AL14: =AF14 -> 2064.8 | AM14: =AL14/AA14 -> 0.54784576 | AN14: =AG14 -> 469.144 | AO14: =AN14/AA14 -> 0.12447625 | AP14: =AH14 -> 1235 | AQ14: =AP14/AA14 -> 0.32767799
A15: 8 | B15: 08 | C15: 212.4 | D15: 15.548 | E15: 55 | F15: =SUM(C15:E15) -> 282.948 | G15: 415.2 | H15: 31.772 | I15: 330 | J15: =SUM(G15:I15) -> 776.972 | K15: 14 | L15: 16.224 | N15: =SUM(K15:M15) -> 30.224 | O15: 414.4 | P15: =((((45.8+1)*1.3)*1.3)*2)*2 -> 316.368 | Q15: 400 | R15: =SUM(O15:Q15) -> 1130.768 | S15: 40 | T15: =((((1+2)*1.3)*1.3)*2)*2 -> 20.28 | U15: 60 | V15: =SUM(S15:U15) -> 120.28 | W15: 160 | X15: 6.76 | Y15: 125 | Z15: =SUM(W15:Y15) -> 291.76 | AA15: =(F15+J15+N15+R15+V15+Z15) -> 2632.952 | AB15: kg/hari | AD15: 8 | AE15: 08 | AF15: =(C15+G15+K15+O15+S15+W15) -> 1256 | AG15: =(D15+H15+L15+P15+T15+X15) -> 406.952 | AH15: =(E15+I15+M15+Q15++U15+Y15) -> 970 | AJ15: 8 | AK15: 08 | AL15: =AF15 -> 1256 | AM15: =AL15/AA15 -> 0.4770311 | AN15: =AG15 -> 406.952 | AO15: =AN15/AA15 -> 0.15456112 | AP15: =AH15 -> 970 | AQ15: =AP15/AA15 -> 0.36840778
